Workbook

Sheet Sheet1
A2: twtarn=1 | B2: tanlen=2 | C2: CARLIN all | D2: CARLIN div | E2: TW all | F2: TW div | G2: Both Alg all | H2: Both alg div | I2: CARLIN triplet | J2: TW triplet | K2: both triplet | L2: twtarn=1 | M2: tanlen=3 | N2: CARLIN all | O2: CARLIN div | P2: TW all | Q2: TW div | R2: Both Alg all | S2: Both alg div | T2: CARLIN triplet | U2: TW triplet | V2: both triplet | W2: twtarn=1 | X2: tanlen=4 | Y2: CARLIN all | Z2: CARLIN div | AA2: TW all | AB2: TW div | AC2: Both Alg all | AD2: Both alg div | AE2: CARLIN triplet | AF2: TW triplet | AG2: both triplet | AH2: twtarn=1 | AI2: tanlen=5 | AJ2: CARLIN all | AK2: CARLIN div | AL2: TW all | AM2: TW div | AN2: Both Alg all | AO2: Both alg div | AP2: CARLIN triplet | AQ2: TW triplet | AR2: both triplet
C3: 30 | D3: 30 | E3: 10 | F3: 10 | G3: 53.333333 | H3: 53.333333 | I3: 89.21371 | J3: 40.262097 | K3: 54.193548 | N3: 40 | O3: 40 | P3: 10 | Q3: 10 | R3: 63.333333 | S3: 63.333333 | T3: 56.169355 | U3: 36.350806 | V3: 54.193548 | Y3: 43.333333 | Z3: 43.333333 | AA3: 40 | AB3: 40 | AC3: 50 | AD3: 50 | AE3: 51.350806 | AF3: 83.205645 | AG3: 57.157258 | AJ3: 40 | AK3: 40 | AL3: 10 | AM3: 10 | AN3: 46.666667 | AO3: 46.666667 | AP3: 44.314516 | AQ3: 56.814516 | AR3: 51.854839
C4: 56.666667 | D4: 56.666667 | E4: 26.666667 | F4: 26.666667 | G4: 80 | H4: 80 | I4: 53.306452 | J4: 87.03629 | K4: 98.629032 | N4: 60 | O4: 60 | P4: 23.333333 | Q4: 23.333333 | R4: 80 | S4: 80 | T4: 94.254032 | U4: 46.673387 | V4: 58.548387 | Y4: 60 | Z4: 60 | AA4: 23.333333 | AB4: 23.333333 | AC4: 60 | AD4: 60 | AE4: 88.145161 | AF4: 85.383065 | AG4: 88.145161 | AJ4: 20 | AK4: 20 | AL4: 6.6666667 | AM4: 6.6666667 | AN4: 36.666667 | AO4: 36.666667 | AP4: 86.008065 | AQ4: 31.915323 | AR4: 85.987903
C5: 43.333333 | D5: 43.333333 | E5: 3.3333333 | F5: 3.3333333 | G5: 50 | H5: 50 | I5: 93.790323 | J5: 30.544355 | K5: 93.145161 | N5: 60 | O5: 60 | P5: 6.6666667 | Q5: 6.6666667 | R5: 53.333333 | S5: 53.333333 | T5: 95.645161 | U5: 32.177419 | V5: 95.604839 | Y5: 60 | Z5: 60 | AA5: 6.6666667 | AB5: 6.6666667 | AC5: 63.333333 | AD5: 63.333333 | AE5: 48.709677 | AF5: 36.592742 | AG5: 48.629032 | AJ5: 53.333333 | AK5: 53.333333 | AL5: 10 | AM5: 10 | AN5: 46.666667 | AO5: 46.666667 | AP5: 53.951613 | AQ5: 44.778226 | AR5: 49.435484
C6: 50 | D6: 50 | E6: 33.333333 | F6: 33.333333 | G6: 63.333333 | H6: 63.333333 | I6: 37.822581 | J6: 47.741935 | K6: 51.370968 | N6: 70 | O6: 70 | P6: 13.333333 | Q6: 13.333333 | R6: 73.333333 | S6: 73.333333 | T6: 93.951613 | U6: 40.705645 | V6: 94.596774 | Y6: 76.666667 | Z6: 76.666667 | AA6: 20 | AB6: 20 | AC6: 86.666667 | AD6: 86.666667 | AE6: 98.689516 | AF6: 35.504032 | AG6: 99.274194 | AJ6: 56.666667 | AK6: 56.666667 | AL6: 26.666667 | AM6: 26.666667 | AN6: 66.666667 | AO6: 66.666667 | AP6: 95.100806 | AQ6: 86.653226 | AR6: 96.108871
C7: 36.666667 | D7: 36.666667 | E7: 3.3333333 | F7: 3.3333333 | G7: 36.666667 | H7: 36.666667 | I7: 51.794355 | J7: 39.758065 | K7: 45 | N7: 40 | O7: 40 | P7: 23.333333 | Q7: 23.333333 | R7: 46.666667 | S7: 46.666667 | T7: 70.282258 | U7: 58.729839 | V7: 70.362903 | Y7: 46.666667 | Z7: 46.666667 | AA7: 20 | AB7: 20 | AC7: 43.333333 | AD7: 43.333333 | AE7: 41.108871 | AF7: 76.229839 | AG7: 67.177419 | AJ7: 53.333333 | AK7: 53.333333 | AL7: 30 | AM7: 30 | AN7: 53.333333 | AO7: 53.333333 | AP7: 45.564516 | AQ7: 87.600806 | AR7: 88.689516
C8: 43.333333 | D8: 43.333333 | E8: 6.6666667 | F8: 6.6666667 | G8: 43.333333 | H8: 43.333333 | I8: 91.733871 | J8: 43.245968 | K8: 91.733871 | N8: 43.333333 | O8: 43.333333 | P8: 6.6666667 | Q8: 6.6666667 | R8: 56.666667 | S8: 56.666667 | T8: 41.048387 | U8: 40.120968 | V8: 54.596774 | Y8: 40 | Z8: 40 | AA8: 30 | AB8: 30 | AC8: 50 | AD8: 50 | AE8: 92.298387 | AF8: 86.310484 | AG8: 92.923387 | AJ8: 46.666667 | AK8: 46.666667 | AL8: 6.6666667 | AM8: 6.6666667 | AN8: 50 | AO8: 50 | AP8: 55.725806 | AQ8: 36.814516 | AR8: 55.020161
C9: 26.666667 | D9: 26.666667 | E9: 16.666667 | F9: 16.666667 | G9: 40 | H9: 40 | I9: 50.645161 | J9: 86.209677 | K9: 88.024194 | N9: 46.666667 | O9: 46.666667 | P9: 10 | Q9: 10 | R9: 60 | S9: 60 | T9: 42.33871 | U9: 39.395161 | V9: 48.145161 | Y9: 40 | Z9: 40 | AA9: 10 | AB9: 10 | AC9: 46.666667 | AD9: 46.666667 | AE9: 36.068548 | AF9: 46.774194 | AG9: 54.959677 | AJ9: 53.333333 | AK9: 53.333333 | AL9: 6.6666667 | AM9: 6.6666667 | AN9: 73.333333 | AO9: 73.333333 | AP9: 93.366935 | AQ9: 74.092742 | AR9: 98.064516
C10: 30 | D10: 30 | E10: 30 | F10: 30 | G10: 50 | H10: 50 | I10: 42.923387 | J10: 49.979839 | K10: 47.419355 | N10: 40 | O10: 40 | P10: 10 | Q10: 10 | R10: 46.666667 | S10: 46.666667 | T10: 53.850806 | U10: 45.927419 | V10: 42.177419 | Y10: 53.333333 | Z10: 53.333333 | AA10: 3.3333333 | AB10: 3.3333333 | AC10: 36.666667 | AD10: 36.666667 | AE10: 56.310484 | AF10: 35.927419 | AG10: 40.967742 | AJ10: 33.333333 | AK10: 33.333333 | AL10: 20 | AM10: 20 | AN10: 46.666667 | AO10: 46.666667 | AP10: 40.342742 | AQ10: 33.810484 | AR10: 40.564516
C11: 56.666667 | D11: 56.666667 | E11: 0 | F11: 0 | G11: 56.666667 | H11: 56.666667 | I11: 56.532258 | J11: 37.439516 | K11: 56.532258 | N11: 60 | O11: 60 | P11: 3.3333333 | Q11: 3.3333333 | R11: 56.666667 | S11: 56.666667 | T11: 42.5 | U11: 35.362903 | V11: 43.306452 | Y11: 40 | Z11: 40 | AA11: 36.666667 | AB11: 36.666667 | AC11: 66.666667 | AD11: 66.666667 | AE11: 48.145161 | AF11: 90.685484 | AG11: 93.306452 | AJ11: 53.333333 | AK11: 53.333333 | AL11: 16.666667 | AM11: 16.666667 | AN11: 50 | AO11: 50 | AP11: 54.274194 | AQ11: 66.653226 | AR11: 57.237903
C12: 33.333333 | D12: 33.333333 | E12: 26.666667 | F12: 26.666667 | G12: 43.333333 | H12: 43.333333 | I12: 77.943548 | J12: 50.262097 | K12: 83.427419 | N12: 60 | O12: 60 | P12: 43.333333 | Q12: 43.333333 | R12: 53.333333 | S12: 53.333333 | T12: 46.129032 | U12: 79.495968 | V12: 39.334677 | Y12: 53.333333 | Z12: 53.333333 | AA12: 16.666667 | AB12: 16.666667 | AC12: 70 | AD12: 70 | AE12: 46.774194 | AF12: 43.487903 | AG12: 48.225806 | AJ12: 36.666667 | AK12: 36.666667 | AL12: 10 | AM12: 10 | AN12: 36.666667 | AO12: 36.666667 | AP12: 43.528226 | AQ12: 38.770161 | AR12: 43.850806
B13: avg | C13: =AVERAGE(C3:C12) -> 40.666667 | D13: =AVERAGE(D3:D12) -> 40.666667 | E13: =AVERAGE(E3:E12) -> 15.666667 | F13: =AVERAGE(F3:F12) -> 15.666667 | G13: =AVERAGE(G3:G12) -> 51.666667 | H13: =AVERAGE(H3:H12) -> 51.666667 | I13: =AVERAGE(I3:I12) -> 64.570565 | J13: =AVERAGE(J3:J12) -> 51.247984 | K13: =AVERAGE(K3:K12) -> 70.947581 | M13: avg | N13: =AVERAGE(N3:N12) -> 52 | O13: =AVERAGE(O3:O12) -> 52 | P13: =AVERAGE(P3:P12) -> 15 | Q13: =AVERAGE(Q3:Q12) -> 15 | R13: =AVERAGE(R3:R12) -> 59 | S13: =AVERAGE(S3:S12) -> 59 | T13: =AVERAGE(T3:T12) -> 63.616935 | U13: =AVERAGE(U3:U12) -> 45.493952 | V13: =AVERAGE(V3:V12) -> 60.086694 | X13: avg | Y13: =AVERAGE(Y3:Y12) -> 51.333333 | Z13: =AVERAGE(Z3:Z12) -> 51.333333 | AA13: =AVERAGE(AA3:AA12) -> 20.666667 | AB13: =AVERAGE(AB3:AB12) -> 20.666667 | AC13: =AVERAGE(AC3:AC12) -> 57.333333 | AD13: =AVERAGE(AD3:AD12) -> 57.333333 | AE13: =AVERAGE(AE3:AE12) -> 60.760081 | AF13: =AVERAGE(AF3:AF12) -> 62.010081 | AG13: =AVERAGE(AG3:AG12) -> 69.076613 | AI13: avg | AJ13: =AVERAGE(AJ3:AJ12) -> 44.666667 | AK13: =AVERAGE(AK3:AK12) -> 44.666667 | AL13: =AVERAGE(AL3:AL12) -> 14.333333 | AM13: =AVERAGE(AM3:AM12) -> 14.333333 | AN13: =AVERAGE(AN3:AN12) -> 50.666667 | AO13: =AVERAGE(AO3:AO12) -> 50.666667 | AP13: =AVERAGE(AP3:AP12) -> 61.217742 | AQ13: =AVERAGE(AQ3:AQ12) -> 55.790323 | AR13: =AVERAGE(AR3:AR12) -> 66.681452
B14: stdev | C14: =_xlfn.STDEV.S(C3:C12) -> 11.088867 | D14: =_xlfn.STDEV.S(D3:D12) -> 11.088867 | E14: =_xlfn.STDEV.S(E3:E12) -> 12.575697 | F14: =_xlfn.STDEV.S(F3:F12) -> 12.575697 | G14: =_xlfn.STDEV.S(G3:G12) -> 12.789849 | H14: =_xlfn.STDEV.S(H3:H12) -> 12.789849 | I14: =_xlfn.STDEV.S(I3:I12) -> 21.370953 | J14: =_xlfn.STDEV.S(J3:J12) -> 19.590388 | K14: =_xlfn.STDEV.S(K3:K12) -> 21.697464 | M14: stdev | N14: =_xlfn.STDEV.S(N3:N12) -> 11.133311 | O14: =_xlfn.STDEV.S(O3:O12) -> 11.133311 | P14: =_xlfn.STDEV.S(P3:P12) -> 11.992796 | Q14: =_xlfn.STDEV.S(Q3:Q12) -> 11.992796 | R14: =_xlfn.STDEV.S(R3:R12) -> 10.778351 | S14: =_xlfn.STDEV.S(S3:S12) -> 10.778351 | T14: =_xlfn.STDEV.S(T3:T12) -> 23.078985 | U14: =_xlfn.STDEV.S(U3:U12) -> 14.08491 | V14: =_xlfn.STDEV.S(V3:V12) -> 20.550438 | X14: stdev | Y14: =_xlfn.STDEV.S(Y3:Y12) -> 11.884215 | Z14: =_xlfn.STDEV.S(Z3:Z12) -> 11.884215 | AA14: =_xlfn.STDEV.S(AA3:AA12) -> 12.252488 | AB14: =_xlfn.STDEV.S(AB3:AB12) -> 12.252488 | AC14: =_xlfn.STDEV.S(AC3:AC12) -> 14.890547 | AD14: =_xlfn.STDEV.S(AD3:AD12) -> 14.890547 | AE14: =_xlfn.STDEV.S(AE3:AE12) -> 23.063627 | AF14: =_xlfn.STDEV.S(AF3:AF12) -> 24.070864 | AG14: =_xlfn.STDEV.S(AG3:AG12) -> 22.158999 | AI14: stdev | AJ14: =_xlfn.STDEV.S(AJ3:AJ12) -> 11.884215 | AK14: =_xlfn.STDEV.S(AK3:AK12) -> 11.884215 | AL14: =_xlfn.STDEV.S(AL3:AL12) -> 8.6137989 | AM14: =_xlfn.STDEV.S(AM3:AM12) -> 8.6137989 | AN14: =_xlfn.STDEV.S(AN3:AN12) -> 11.632224 | AO14: =_xlfn.STDEV.S(AO3:AO12) -> 11.632224 | AP14: =_xlfn.STDEV.S(AP3:AP12) -> 21.619926 | AQ14: =_xlfn.STDEV.S(AQ3:AQ12) -> 21.711795 | AR14: =_xlfn.STDEV.S(AR3:AR12) -> 22.73938
A18: twtarn=3 | B18: tanlen=2 | C18: CARLIN all | D18: CARLIN div | E18: TW all | F18: TW div | G18: Both Alg all | H18: Both alg div | I18: CARLIN triplet | J18: TW triplet | K18: both triplet | L18: twtarn=3 | M18: tanlen=3 | N18: CARLIN all | O18: CARLIN div | P18: TW all | Q18: TW div | R18: Both Alg all | S18: Both alg div | T18: CARLIN triplet | U18: TW triplet | V18: both triplet | W18: twtarn=3 | X18: tanlen=4 | Y18: CARLIN all | Z18: CARLIN div | AA18: TW all | AB18: TW div | AC18: Both Alg all | AD18: Both alg div | AE18: CARLIN triplet | AF18: TW triplet | AG18: both triplet | AH18: twtarn=3 | AI18: tanlen=5 | AJ18: CARLIN all | AK18: CARLIN div | AL18: TW all | AM18: TW div | AN18: Both Alg all | AO18: Both alg div | AP18: CARLIN triplet | AQ18: TW triplet | AR18: both triplet
C19: 56.666667 | D19: 56.666667 | E19: 13.333333 | F19: 13.333333 | G19: 73.333333 | H19: 73.333333 | I19: 43.951613 | J19: 77.701613 | K19: 94.032258 | N19: 56.666667 | O19: 56.666667 | P19: 53.333333 | Q19: 53.333333 | R19: 60 | S19: 60 | T19: 72.177419 | U19: 88.245968 | V19: 72.379032 | Y19: 63.333333 | Z19: 63.333333 | AA19: 26.666667 | AB19: 26.666667 | AC19: 63.333333 | AD19: 63.333333 | AE19: 94.435484 | AF19: 79.153226 | AG19: 94.435484 | AJ19: 20 | AK19: 20 | AL19: 53.333333 | AM19: 53.333333 | AN19: 30 | AO19: 30 | AP19: 41.129032 | AQ19: 51.854839 | AR19: 40.342742
C20: 40 | D20: 40 | E20: 66.666667 | F20: 66.666667 | G20: 86.666667 | H20: 86.666667 | I20: 87.540323 | J20: 94.032258 | K20: 94.193548 | N20: 60 | O20: 60 | P20: 30 | Q20: 30 | R20: 86.666667 | S20: 86.666667 | T20: 98.306452 | U20: 91.229839 | V20: 99.274194 | Y20: 56.666667 | Z20: 56.666667 | AA20: 30 | AB20: 30 | AC20: 80 | AD20: 80 | AE20: 55.866935 | AF20: 55.201613 | AG20: 53.467742 | AJ20: 33.333333 | AK20: 33.333333 | AL20: 56.666667 | AM20: 56.666667 | AN20: 80 | AO20: 80 | AP20: 86.895161 | AQ20: 55.705645 | AR20: 94.677419
C21: 46.666667 | D21: 46.666667 | E21: 33.333333 | F21: 33.333333 | G21: 66.666667 | H21: 66.666667 | I21: 86.955645 | J21: 87.822581 | K21: 94.516129 | N21: 46.666667 | O21: 46.666667 | P21: 66.666667 | Q21: 66.666667 | R21: 86.666667 | S21: 86.666667 | T21: 42.177419 | U21: 88.870968 | V21: 94.758065 | Y21: 66.666667 | Z21: 66.666667 | AA21: 50 | AB21: 50 | AC21: 76.666667 | AD21: 76.666667 | AE21: 69.435484 | AF21: 52.620968 | AG21: 94.596774 | AJ21: 50 | AK21: 50 | AL21: 30 | AM21: 30 | AN21: 66.666667 | AO21: 66.666667 | AP21: 47.33871 | AQ21: 68.75 | AR21: 57.822581
C22: 70 | D22: 70 | E22: 63.333333 | F22: 63.333333 | G22: 93.333333 | H22: 93.333333 | I22: 57.96371 | J22: 84.576613 | K22: 99.919355 | N22: 33.333333 | O22: 33.333333 | P22: 46.666667 | Q22: 46.666667 | R22: 86.666667 | S22: 86.666667 | T22: 97.33871 | U22: 49.354839 | V22: 99.274194 | Y22: 56.666667 | Z22: 56.666667 | AA22: 60 | AB22: 60 | AC22: 83.333333 | AD22: 83.333333 | AE22: 41.270161 | AF22: 55.887097 | AG22: 99.193548 | AJ22: 63.333333 | AK22: 63.333333 | AL22: 20 | AM22: 20 | AN22: 93.333333 | AO22: 93.333333 | AP22: 48.608871 | AQ22: 48.951613 | AR22: 99.919355
C23: 30 | D23: 30 | E23: 26.666667 | F23: 26.666667 | G23: 30 | H23: 30 | I23: 49.53629 | J23: 55.383065 | K23: 48.326613 | N23: 86.666667 | O23: 86.666667 | P23: 66.666667 | Q23: 66.666667 | R23: 76.666667 | S23: 76.666667 | T23: 94.193548 | U23: 93.487903 | V23: 93.467742 | Y23: 70 | Z23: 70 | AA23: 60 | AB23: 60 | AC23: 86.666667 | AD23: 86.666667 | AE23: 57.258065 | AF23: 52.741935 | AG23: 58.629032 | AJ23: 43.333333 | AK23: 43.333333 | AL23: 66.666667 | AM23: 66.666667 | AN23: 93.333333 | AO23: 93.333333 | AP23: 46.008065 | AQ23: 93.951613 | AR23: 99.919355
C24: 46.666667 | D24: 46.666667 | E24: 66.666667 | F24: 66.666667 | G24: 53.333333 | H24: 53.333333 | I24: 52.177419 | J24: 94.435484 | K24: 88.548387 | N24: 50 | O24: 50 | P24: 53.333333 | Q24: 53.333333 | R24: 66.666667 | S24: 66.666667 | T24: 98.205645 | U24: 98.427419 | V24: 98.951613 | Y24: 53.333333 | Z24: 53.333333 | AA24: 60 | AB24: 60 | AC24: 66.666667 | AD24: 66.666667 | AE24: 43.28629 | AF24: 93.467742 | AG24: 56.612903 | AJ24: 40 | AK24: 40 | AL24: 60 | AM24: 60 | AN24: 66.666667 | AO24: 66.666667 | AP24: 57.116935 | AQ24: 93.75 | AR24: 95.544355
C25: 43.333333 | D25: 43.333333 | E25: 30 | F25: 30 | G25: 70 | H25: 70 | I25: 91.71371 | J25: 49.274194 | K25: 93.447581 | N25: 56.666667 | O25: 56.666667 | P25: 76.666667 | Q25: 76.666667 | R25: 86.666667 | S25: 86.666667 | T25: 93.366935 | U25: 94.596774 | V25: 99.274194 | Y25: 40 | Z25: 40 | AA25: 33.333333 | AB25: 33.333333 | AC25: 80 | AD25: 80 | AE25: 90.887097 | AF25: 35.262097 | AG25: 94.193548 | AJ25: 23.333333 | AK25: 23.333333 | AL25: 53.333333 | AM25: 53.333333 | AN25: 63.333333 | AO25: 63.333333 | AP25: 85.725806 | AQ25: 54.778226 | AR25: 93.850806
C26: 36.666667 | D26: 36.666667 | E26: 33.333333 | F26: 33.333333 | G26: 43.333333 | H26: 43.333333 | I26: 43.689516 | J26: 92.983871 | K26: 54.133065 | N26: 53.333333 | O26: 53.333333 | P26: 50 | Q26: 50 | R26: 46.666667 | S26: 46.666667 | T26: 70.060484 | U26: 52.076613 | V26: 80.524194 | Y26: 70 | Z26: 70 | AA26: 60 | AB26: 60 | AC26: 86.666667 | AD26: 86.666667 | AE26: 98.689516 | AF26: 68.951613 | AG26: 99.274194 | AJ26: 56.666667 | AK26: 56.666667 | AL26: 40 | AM26: 40 | AN26: 66.666667 | AO26: 66.666667 | AP26: 56.653226 | AQ26: 43.58871 | AR26: 55.403226
C27: 56.666667 | D27: 56.666667 | E27: 43.333333 | F27: 43.333333 | G27: 76.666667 | H27: 76.666667 | I27: 94.012097 | J27: 53.629032 | K27: 94.596774 | N27: 43.333333 | O27: 43.333333 | P27: 56.666667 | Q27: 56.666667 | R27: 80 | S27: 80 | T27: 88.125 | U27: 93.366935 | V27: 94.112903 | Y27: 43.333333 | Z27: 43.333333 | AA27: 60 | AB27: 60 | AC27: 86.666667 | AD27: 86.666667 | AE27: 92.237903 | AF27: 92.318548 | AG27: 99.274194 | AJ27: 60 | AK27: 60 | AL27: 23.333333 | AM27: 23.333333 | AN27: 100 | AO27: 100 | AP27: 46.370968 | AQ27: 90.907258 | AR27: 100
C28: 63.333333 | D28: 63.333333 | E28: 53.333333 | F28: 53.333333 | G28: 80 | H28: 80 | I28: 94.092742 | J28: 97.096774 | K28: 94.758065 | N28: 43.333333 | O28: 43.333333 | P28: 36.666667 | Q28: 36.666667 | R28: 70 | S28: 70 | T28: 51.290323 | U28: 61.08871 | V28: 57.258065 | Y28: 56.666667 | Z28: 56.666667 | AA28: 100 | AB28: 100 | AC28: 86.666667 | AD28: 86.666667 | AE28: 46.612903 | AF28: 100 | AG28: 99.274194 | AJ28: 36.666667 | AK28: 36.666667 | AL28: 66.666667 | AM28: 66.666667 | AN28: 60 | AO28: 60 | AP28: 48.326613 | AQ28: 96.108871 | AR28: 56.673387
B29: avg | C29: =AVERAGE(C19:C28) -> 49 | D29: =AVERAGE(D19:D28) -> 49 | E29: =AVERAGE(E19:E28) -> 43 | F29: =AVERAGE(F19:F28) -> 43 | G29: =AVERAGE(G19:G28) -> 67.333333 | H29: =AVERAGE(H19:H28) -> 67.333333 | I29: =AVERAGE(I19:I28) -> 70.163306 | J29: =AVERAGE(J19:J28) -> 78.693548 | K29: =AVERAGE(K19:K28) -> 85.647177 | M29: avg | N29: =AVERAGE(N19:N28) -> 53 | O29: =AVERAGE(O19:O28) -> 53 | P29: =AVERAGE(P19:P28) -> 53.666667 | Q29: =AVERAGE(Q19:Q28) -> 53.666667 | R29: =AVERAGE(R19:R28) -> 74.666667 | S29: =AVERAGE(S19:S28) -> 74.666667 | T29: =AVERAGE(T19:T28) -> 80.524194 | U29: =AVERAGE(U19:U28) -> 81.074597 | V29: =AVERAGE(V19:V28) -> 88.927419 | X29: avg | Y29: =AVERAGE(Y19:Y28) -> 57.666667 | Z29: =AVERAGE(Z19:Z28) -> 57.666667 | AA29: =AVERAGE(AA19:AA28) -> 54 | AB29: =AVERAGE(AB19:AB28) -> 54 | AC29: =AVERAGE(AC19:AC28) -> 79.666667 | AD29: =AVERAGE(AD19:AD28) -> 79.666667 | AE29: =AVERAGE(AE19:AE28) -> 68.997984 | AF29: =AVERAGE(AF19:AF28) -> 68.560484 | AG29: =AVERAGE(AG19:AG28) -> 84.895161 | AI29: avg | AJ29: =AVERAGE(AJ19:AJ28) -> 42.666667 | AK29: =AVERAGE(AK19:AK28) -> 42.666667 | AL29: =AVERAGE(AL19:AL28) -> 47 | AM29: =AVERAGE(AM19:AM28) -> 47 | AN29: =AVERAGE(AN19:AN28) -> 72 | AO29: =AVERAGE(AO19:AO28) -> 72 | AP29: =AVERAGE(AP19:AP28) -> 56.417339 | AQ29: =AVERAGE(AQ19:AQ28) -> 69.834677 | AR29: =AVERAGE(AR19:AR28) -> 79.415323
B30: stdev | C30: =_xlfn.STDEV.S(C19:C28) -> 12.47714 | D30: =_xlfn.STDEV.S(D19:D28) -> 12.47714 | E30: =_xlfn.STDEV.S(E19:E28) -> 18.688479 | F30: =_xlfn.STDEV.S(F19:F28) -> 18.688479 | G30: =_xlfn.STDEV.S(G19:G28) -> 19.739038 | H30: =_xlfn.STDEV.S(H19:H28) -> 19.739038 | I30: =_xlfn.STDEV.S(I19:I28) -> 22.299617 | J30: =_xlfn.STDEV.S(J19:J28) -> 18.803124 | K30: =_xlfn.STDEV.S(K19:K28) -> 18.390922 | M30: stdev | N30: =_xlfn.STDEV.S(N19:N28) -> 14.268155 | O30: =_xlfn.STDEV.S(O19:O28) -> 14.268155 | P30: =_xlfn.STDEV.S(P19:P28) -> 14.09404 | Q30: =_xlfn.STDEV.S(Q19:Q28) -> 14.09404 | R30: =_xlfn.STDEV.S(R19:R28) -> 13.716711 | S30: =_xlfn.STDEV.S(S19:S28) -> 13.716711 | T30: =_xlfn.STDEV.S(T19:T28) -> 20.616558 | U30: =_xlfn.STDEV.S(U19:U28) -> 19.005742 | V30: =_xlfn.STDEV.S(V19:V28) -> 14.339391 | X30: stdev | Y30: =_xlfn.STDEV.S(Y19:Y28) -> 10.31001 | Z30: =_xlfn.STDEV.S(Z19:Z28) -> 10.31001 | AA30: =_xlfn.STDEV.S(AA19:AA28) -> 21.245188 | AB30: =_xlfn.STDEV.S(AB19:AB28) -> 21.245188 | AC30: =_xlfn.STDEV.S(AC19:AC28) -> 8.5273706 | AD30: =_xlfn.STDEV.S(AD19:AD28) -> 8.5273706 | AE30: =_xlfn.STDEV.S(AE19:AE28) -> 23.068346 | AF30: =_xlfn.STDEV.S(AF19:AF28) -> 21.699388 | AG30: =_xlfn.STDEV.S(AG19:AG28) -> 19.927064 | AI30: stdev | AJ30: =_xlfn.STDEV.S(AJ19:AJ28) -> 14.890547 | AK30: =_xlfn.STDEV.S(AK19:AK28) -> 14.890547 | AL30: =_xlfn.STDEV.S(AL19:AL28) -> 17.458947 | AM30: =_xlfn.STDEV.S(AM19:AM28) -> 17.458947 | AN30: =_xlfn.STDEV.S(AN19:AN28) -> 20.620019 | AO30: =_xlfn.STDEV.S(AO19:AO28) -> 20.620019 | AP30: =_xlfn.STDEV.S(AP19:AP28) -> 16.466456 | AQ30: =_xlfn.STDEV.S(AQ19:AQ28) -> 21.508879 | AR30: =_xlfn.STDEV.S(AR19:AR28) -> 23.694138
A33: twtarn=5 | C33: 56.666667 | D33: 56.666667 | E33: 83.333333 | F33: 83.333333 | G33: 93.333333 | H33: 93.333333 | I33: 66.129032 | J33: 99.334677 | K33: 99.919355 | N33: 56.666667 | O33: 56.666667 | P33: 100 | Q33: 100 | R33: 80 | S33: 80 | T33: 57.96371 | U33: 100 | V33: 89.677419 | Y33: 30 | Z33: 30 | AA33: 80 | AB33: 80 | AC33: 43.333333 | AD33: 43.333333 | AE33: 68.326613 | AF33: 94.677419 | AG33: 90.846774 | AJ33: 36.666667 | AK33: 36.666667 | AL33: 83.333333 | AM33: 83.333333 | AN33: 80 | AO33: 80 | AP33: 51.995968 | AQ33: 57.419355 | AR33: 94.112903
C34: 53.333333 | D34: 53.333333 | E34: 73.333333 | F34: 73.333333 | G34: 93.333333 | H34: 93.333333 | I34: 48.568548 | J34: 98.548387 | K34: 99.354839 | N34: 56.666667 | O34: 56.666667 | P34: 100 | Q34: 100 | R34: 86.666667 | S34: 86.666667 | T34: 56.532258 | U34: 100 | V34: 58.064516 | Y34: 66.666667 | Z34: 66.666667 | AA34: 73.333333 | AB34: 73.333333 | AC34: 63.333333 | AD34: 63.333333 | AE34: 42.580645 | AF34: 89.516129 | AG34: 41.854839 | AJ34: 43.333333 | AK34: 43.333333 | AL34: 86.666667 | AM34: 86.666667 | AN34: 86.666667 | AO34: 86.666667 | AP34: 55.241935 | AQ34: 94.758065 | AR34: 99.274194
C35: 43.333333 | D35: 43.333333 | E35: 80 | F35: 80 | G35: 73.333333 | H35: 73.333333 | I35: 51.572581 | J35: 99.193548 | K35: 94.112903 | N35: 33.333333 | O35: 33.333333 | P35: 73.333333 | Q35: 73.333333 | R35: 86.666667 | S35: 86.666667 | T35: 50.685484 | U35: 52.903226 | V35: 94.193548 | Y35: 36.666667 | Z35: 36.666667 | AA35: 63.333333 | AB35: 63.333333 | AC35: 86.666667 | AD35: 86.666667 | AE35: 67.96371 | AF35: 98.044355 | AG35: 99.354839 | AJ35: 56.666667 | AK35: 56.666667 | AL35: 33.333333 | AM35: 33.333333 | AN35: 100 | AO35: 100 | AP35: 52.802419 | AQ35: 51.875 | AR35: 100
C36: 63.333333 | D36: 63.333333 | E36: 76.666667 | F36: 76.666667 | G36: 63.333333 | H36: 63.333333 | I36: 41.612903 | J36: 98.689516 | K36: 42.419355 | N36: 26.666667 | O36: 26.666667 | P36: 63.333333 | Q36: 63.333333 | R36: 66.666667 | S36: 66.666667 | T36: 38.951613 | U36: 98.387097 | V36: 92.862903 | Y36: 33.333333 | Z36: 33.333333 | AA36: 86.666667 | AB36: 86.666667 | AC36: 93.333333 | AD36: 93.333333 | AE36: 49.314516 | AF36: 99.274194 | AG36: 94.83871 | AJ36: 36.666667 | AK36: 36.666667 | AL36: 26.666667 | AM36: 26.666667 | AN36: 66.666667 | AO36: 66.666667 | AP36: 45.080645 | AQ36: 87.177419 | AR36: 94.032258
C37: 63.333333 | D37: 63.333333 | E37: 56.666667 | F37: 56.666667 | G37: 80 | H37: 80 | I37: 47.016129 | J37: 94.072581 | K37: 94.112903 | N37: 40 | O37: 40 | P37: 80 | Q37: 80 | R37: 70 | S37: 70 | T37: 41.592742 | U37: 94.677419 | V37: 45.645161 | Y37: 43.333333 | Z37: 43.333333 | AA37: 63.333333 | AB37: 63.333333 | AC37: 56.666667 | AD37: 56.666667 | AE37: 54.616935 | AF37: 93.850806 | AG37: 54.233871 | AJ37: 43.333333 | AK37: 43.333333 | AL37: 63.333333 | AM37: 63.333333 | AN37: 80 | AO37: 80 | AP37: 53.991935 | AQ37: 47.580645 | AR37: 58.629032
C38: 56.666667 | D38: 56.666667 | E38: 60 | F38: 60 | G38: 73.333333 | H38: 73.333333 | I38: 72.5 | J38: 42.33871 | K38: 57.983871 | N38: 60 | O38: 60 | P38: 93.333333 | Q38: 93.333333 | R38: 100 | S38: 100 | T38: 93.225806 | U38: 94.83871 | V38: 100 | Y38: 40 | Z38: 40 | AA38: 63.333333 | AB38: 63.333333 | AC38: 86.666667 | AD38: 86.666667 | AE38: 48.205645 | AF38: 92.741935 | AG38: 94.758065 | AJ38: 43.333333 | AK38: 43.333333 | AL38: 100 | AM38: 100 | AN38: 80 | AO38: 80 | AP38: 53.366935 | AQ38: 100 | AR38: 94.112903
C39: 53.333333 | D39: 53.333333 | E39: 93.333333 | F39: 93.333333 | G39: 80 | H39: 80 | I39: 68.709677 | J39: 58.709677 | K39: 52.258065 | N39: 40 | O39: 40 | P39: 80 | Q39: 80 | R39: 73.333333 | S39: 73.333333 | T39: 46.370968 | U39: 94.112903 | V39: 93.548387 | Y39: 53.333333 | Z39: 53.333333 | AA39: 60 | AB39: 60 | AC39: 63.333333 | AD39: 63.333333 | AE39: 36.693548 | AF39: 41.129032 | AG39: 40.725806 | AJ39: 46.666667 | AK39: 46.666667 | AL39: 53.333333 | AM39: 53.333333 | AN39: 80 | AO39: 80 | AP39: 51.854839 | AQ39: 93.306452 | AR39: 94.112903
C40: 40 | D40: 40 | E40: 63.333333 | F40: 63.333333 | G40: 70 | H40: 70 | I40: 35.46371 | J40: 93.447581 | K40: 46.129032 | N40: 40 | O40: 40 | P40: 76.666667 | Q40: 76.666667 | R40: 80 | S40: 80 | T40: 51.71371 | U40: 94.596774 | V40: 98.709677 | Y40: 46.666667 | Z40: 46.666667 | AA40: 56.666667 | AB40: 56.666667 | AC40: 70 | AD40: 70 | AE40: 53.004032 | AF40: 98.004032 | AG40: 57.399194 | AJ40: 43.333333 | AK40: 43.333333 | AL40: 93.333333 | AM40: 93.333333 | AN40: 80 | AO40: 80 | AP40: 44.939516 | AQ40: 99.354839 | AR40: 98.709677
C41: 70 | D41: 70 | E41: 60 | F41: 60 | G41: 83.333333 | H41: 83.333333 | I41: 89.435484 | J41: 84.173387 | K41: 94.677419 | N41: 36.666667 | O41: 36.666667 | P41: 70 | Q41: 70 | R41: 40 | S41: 40 | T41: 38.125 | U41: 89.274194 | V41: 41.512097 | Y41: 36.666667 | Z41: 36.666667 | AA41: 46.666667 | AB41: 46.666667 | AC41: 73.333333 | AD41: 73.333333 | AE41: 45.524194 | AF41: 68.870968 | AG41: 93.467742 | AJ41: 56.666667 | AK41: 56.666667 | AL41: 66.666667 | AM41: 66.666667 | AN41: 80 | AO41: 80 | AP41: 55.322581 | AQ41: 97.741935 | AR41: 98.629032
C42: 56.666667 | D42: 56.666667 | E42: 56.666667 | F42: 56.666667 | G42: 83.333333 | H42: 83.333333 | I42: 53.225806 | J42: 93.870968 | K42: 94.677419 | N42: 60 | O42: 60 | P42: 60 | Q42: 60 | R42: 80 | S42: 80 | T42: 93.366935 | U42: 97.983871 | V42: 98.629032 | Y42: 46.666667 | Z42: 46.666667 | AA42: 73.333333 | AB42: 73.333333 | AC42: 73.333333 | AD42: 73.333333 | AE42: 44.596774 | AF42: 94.274194 | AG42: 43.870968 | AJ42: 60 | AK42: 60 | AL42: 50 | AM42: 50 | AN42: 73.333333 | AO42: 73.333333 | AP42: 36.048387 | AQ42: 55.302419 | AR42: 55.322581
B43: avg | C43: =AVERAGE(C33:C42) -> 55.666667 | D43: =AVERAGE(D33:D42) -> 55.666667 | E43: =AVERAGE(E33:E42) -> 70.333333 | F43: =AVERAGE(F33:F42) -> 70.333333 | G43: =AVERAGE(G33:G42) -> 79.333333 | H43: =AVERAGE(H33:H42) -> 79.333333 | I43: =AVERAGE(I33:I42) -> 57.423387 | J43: =AVERAGE(J33:J42) -> 86.237903 | K43: =AVERAGE(K33:K42) -> 77.564516 | M43: avg | N43: =AVERAGE(N33:N42) -> 45 | O43: =AVERAGE(O33:O42) -> 45 | P43: =AVERAGE(P33:P42) -> 79.666667 | Q43: =AVERAGE(Q33:Q42) -> 79.666667 | R43: =AVERAGE(R33:R42) -> 76.333333 | S43: =AVERAGE(S33:S42) -> 76.333333 | T43: =AVERAGE(T33:T42) -> 56.852823 | U43: =AVERAGE(U33:U42) -> 91.677419 | V43: =AVERAGE(V33:V42) -> 81.284274 | X43: avg | Y43: =AVERAGE(Y33:Y42) -> 43.333333 | Z43: =AVERAGE(Z33:Z42) -> 43.333333 | AA43: =AVERAGE(AA33:AA42) -> 66.666667 | AB43: =AVERAGE(AB33:AB42) -> 66.666667 | AC43: =AVERAGE(AC33:AC42) -> 71 | AD43: =AVERAGE(AD33:AD42) -> 71 | AE43: =AVERAGE(AE33:AE42) -> 51.082661 | AF43: =AVERAGE(AF33:AF42) -> 87.038306 | AG43: =AVERAGE(AG33:AG42) -> 71.135081 | AI43: avg | AJ43: =AVERAGE(AJ33:AJ42) -> 46.666667 | AK43: =AVERAGE(AK33:AK42) -> 46.666667 | AL43: =AVERAGE(AL33:AL42) -> 65.666667 | AM43: =AVERAGE(AM33:AM42) -> 65.666667 | AN43: =AVERAGE(AN33:AN42) -> 80.666667 | AO43: =AVERAGE(AO33:AO42) -> 80.666667 | AP43: =AVERAGE(AP33:AP42) -> 50.064516 | AQ43: =AVERAGE(AQ33:AQ42) -> 78.451613 | AR43: =AVERAGE(AR33:AR42) -> 88.693548
B44: stdev | C44: =_xlfn.STDEV.S(C33:C42) -> 9.0335452 | D44: =_xlfn.STDEV.S(D33:D42) -> 9.0335452 | E44: =_xlfn.STDEV.S(E33:E42) -> 12.80914 | F44: =_xlfn.STDEV.S(F33:F42) -> 12.80914 | G44: =_xlfn.STDEV.S(G33:G42) -> 9.6609178 | H44: =_xlfn.STDEV.S(H33:H42) -> 9.6609178 | I44: =_xlfn.STDEV.S(I33:I42) -> 16.418204 | J44: =_xlfn.STDEV.S(J33:J42) -> 19.739399 | K44: =_xlfn.STDEV.S(K33:K42) -> 24.39296 | M44: stdev | N44: =_xlfn.STDEV.S(N33:N42) -> 12.196944 | O44: =_xlfn.STDEV.S(O33:O42) -> 12.196944 | P44: =_xlfn.STDEV.S(P33:P42) -> 14.181365 | Q44: =_xlfn.STDEV.S(Q33:Q42) -> 14.181365 | R44: =_xlfn.STDEV.S(R33:R42) -> 15.904809 | S44: =_xlfn.STDEV.S(S33:S42) -> 15.904809 | T44: =_xlfn.STDEV.S(T33:T42) -> 20.374226 | U44: =_xlfn.STDEV.S(U33:U42) -> 14.007868 | V44: =_xlfn.STDEV.S(V33:V42) -> 23.25573 | X44: stdev | Y44: =_xlfn.STDEV.S(Y33:Y42) -> 10.772622 | Z44: =_xlfn.STDEV.S(Z33:Z42) -> 10.772622 | AA44: =_xlfn.STDEV.S(AA33:AA42) -> 11.758895 | AB44: =_xlfn.STDEV.S(AB33:AB42) -> 11.758895 | AC44: =_xlfn.STDEV.S(AC33:AC42) -> 15.238839 | AD44: =_xlfn.STDEV.S(AD33:AD42) -> 15.238839 | AE44: =_xlfn.STDEV.S(AE33:AE42) -> 10.339805 | AF44: =_xlfn.STDEV.S(AF33:AF42) -> 18.33214 | AG44: =_xlfn.STDEV.S(AG33:AG42) -> 25.393076 | AI44: stdev | AJ44: =_xlfn.STDEV.S(AJ33:AJ42) -> 8.3147942 | AK44: =_xlfn.STDEV.S(AK33:AK42) -> 8.3147942 | AL44: =_xlfn.STDEV.S(AL33:AL42) -> 25.094882 | AM44: =_xlfn.STDEV.S(AM33:AM42) -> 25.094882 | AN44: =_xlfn.STDEV.S(AN33:AN42) -> 8.5778929 | AO44: =_xlfn.STDEV.S(AO33:AO42) -> 8.5778929 | AP44: =_xlfn.STDEV.S(AP33:AP42) -> 6.1713662 | AQ44: =_xlfn.STDEV.S(AQ33:AQ42) -> 22.295178 | AR44: =_xlfn.STDEV.S(AR33:AR42) -> 16.908017
A50: twtarn=7 | C50: 46.666667 | D50: 46.666667 | E50: 86.666667 | F50: 86.666667 | G50: 66.666667 | H50: 66.666667 | I50: 52.883065 | J50: 94.193548 | K50: 52.822581 | N50: 50 | O50: 50 | P50: 86.666667 | Q50: 86.666667 | R50: 93.333333 | S50: 93.333333 | T50: 89.274194 | U50: 99.83871 | V50: 99.354839 | Y50: 86.666667 | Z50: 86.666667 | AA50: 86.666667 | AB50: 86.666667 | AC50: 100 | AD50: 100 | AE50: 99.274194 | AF50: 99.274194 | AG50: 100 | AJ50: 43.333333 | AK50: 43.333333 | AL50: 86.666667 | AM50: 86.666667 | AN50: 60 | AO50: 60 | AP50: 45.987903 | AQ50: 98.709677 | AR50: 52.177419
C51: 40 | D51: 40 | E51: 73.333333 | F51: 73.333333 | G51: 80 | H51: 80 | I51: 86.733871 | J51: 99.112903 | K51: 99.758065 | N51: 50 | O51: 50 | P51: 93.333333 | Q51: 93.333333 | R51: 66.666667 | S51: 66.666667 | T51: 54.092742 | U51: 94.83871 | V51: 55.403226 | Y51: 46.666667 | Z51: 46.666667 | AA51: 93.333333 | AB51: 93.333333 | AC51: 86.666667 | AD51: 86.666667 | AE51: 44.919355 | AF51: 99.919355 | AG51: 58.629032 | AJ51: 50 | AK51: 50 | AL51: 66.666667 | AM51: 66.666667 | AN51: 60 | AO51: 60 | AP51: 46.370968 | AQ51: 98.548387 | AR51: 48.709677
...

Sheet CARLIN
A1: Carlin RF | B1: Carlin Triplet
D2: rf | E2: triplet
A3: {=Sheet1!C3:C12} -> 30 | B3: {=Sheet1!I3:I12} -> 89.21371 | C3: avg | D3: =AVERAGE(A3:A322) -> 48.072917 | E3: =AVERAGE(B3:B322) -> 60.848853
A4: 56.666667 | B4: 53.306452 | C4: var | D4: =_xlfn.VAR.S(A3:A322) -> 184.32765 | E4: =_xlfn.VAR.S(B3:B322) -> 370.83731
A5: 43.333333 | B5: 93.790323 | C5: std | D5: =_xlfn.STDEV.S(A3:A322) -> 13.576732 | E5: =_xlfn.STDEV.S(B3:B322) -> 19.257137
A6: 50 | B6: 37.822581 | C6: max | D6: =MAX(A3:A322) -> 86.666667 | E6: =MAX(B3:B322) -> 99.758065
A7: 36.666667 | B7: 51.794355 | C7: min | D7: =MIN(A3:A322) -> 13.333333 | E7: =MIN(B3:B322) -> 34.254032
A8: 43.333333 | B8: 91.733871
A9: 26.666667 | B9: 50.645161
A10: 30 | B10: 42.923387
A11: 56.666667 | B11: 56.532258
A12: 33.333333 | B12: 77.943548
A13: {=Sheet1!N3:N12} -> 40 | B13: {=Sheet1!T3:T12} -> 56.169355
A14: 60 | B14: 94.254032
A15: 60 | B15: 95.645161
A16: 70 | B16: 93.951613
A17: 40 | B17: 70.282258
A18: 43.333333 | B18: 41.048387
A19: 46.666667 | B19: 42.33871
A20: 40 | B20: 53.850806
A21: 60 | B21: 42.5
A22: 60 | B22: 46.129032
A23: {=Sheet1!Y3:Y12} -> 43.333333 | B23: {=Sheet1!AE3:AE12} -> 51.350806
A24: 60 | B24: 88.145161
A25: 60 | B25: 48.709677
A26: 76.666667 | B26: 98.689516
A27: 46.666667 | B27: 41.108871
A28: 40 | B28: 92.298387
A29: 40 | B29: 36.068548
A30: 53.333333 | B30: 56.310484
A31: 40 | B31: 48.145161
A32: 53.333333 | B32: 46.774194
A33: {=Sheet1!AJ3:AJ12} -> 40 | B33: {=Sheet1!AP3:AP12} -> 44.314516
A34: 20 | B34: 86.008065
A35: 53.333333 | B35: 53.951613
A36: 56.666667 | B36: 95.100806
A37: 53.333333 | B37: 45.564516
A38: 46.666667 | B38: 55.725806
A39: 53.333333 | B39: 93.366935
A40: 33.333333 | B40: 40.342742
...
